Workbook

Sheet AH2700A2022-04-07
A1: av_exp = 10, frequency = 1591.5, no. of samples = 10, settling samples = 2 | J1: zero_corrected | K1: from G:\Shared drives\MSL - Electricity - Ongoing\Farad\Cap_Scale_Sept_2021\compare 2019 2020.xlsx cell AA30 | M1: AH11C1 | N1: -4.2 | O1: correction | P1: =N1 - N6 -> -2.4318
A2: DateTime | B2: Capacitor | C2: Capacitance (pF) | D2: uCap (pF) | E2: Conductance (nS) | F2: uCond (nS) | G2: Frequency (Hz) | H2: Voltage (V) | J2: Capacitance (pF) | K2: Conductance (nS) | L2: tand | M2: nominal C | N2: error | O2: corrected ppm
A3: 44658.421 | B3: zero | C3: -4e-08 | D3: 4.2895221e-08 | E3: 2.718e-05 | F3: 7.9598995e-07 | G3: 1591.5 | H3: 15 | I3: AH2 leads (long BNC), 1019.35 mb, 20.9 deg, 54.9 % RH | J3: =C3-C$3 -> 0 | K3: =D3-D$3 -> 0 | L3: - | N3: ppm
A4: 44658.424 | B4: ah11a1 | C4: 9.9999754 | D4: 7.4859869e-08 | E4: -0.00016312 | F4: 1.422533e-06 | G4: 1591.5 | H4: 15 | I4: 11.9, -11.7, .034, -.017, -.012, .020 … forgot chassis temperature! | J4: =C4-C$3 -> 9.9999755 | K4: =E4-E$3 -> -0.0001903 | L4: =K4*0.000000001/(2*PI()*J4*G4*0.000000000001) -> -1.9030638e-06 | M4: 10 | N4: =(J4/M4-1)*1000000 -> -2.4516 | O4: =N4+P$1 -> -4.8834
A5: 44658.426 | B5: ah11b1 | C5: 9.9999779 | D5: 6.9921385e-08 | E5: -0.00010869 | F5: 1.3133545e-06 | G5: 1591.5 | H5: 15 | J5: =C5-C$3 -> 9.9999779 | K5: =E5-E$3 -> -0.00013587 | L5: =K5*0.000000001/(2*PI()*J5*G5*0.000000000001) -> -1.3587452e-06 | M5: 10 | N5: =(J5/M5-1)*1000000 -> -2.2109 | O5: =N5+P$1 -> -4.6427
A6: 44658.427 | B6: ah11c1 | C6: 99.999823 | D6: 1.0198039e-07 | E6: 0.0017119 | F6: 9.4339811e-07 | G6: 1591.5 | H6: 15 | J6: =C6-C$3 -> 99.999823 | K6: =E6-E$3 -> 0.00168472 | L6: =K6*0.000000001/(2*PI()*J6*G6*0.000000000001) -> 1.6847753e-06 | M6: 100 | N6: =(J6/M6-1)*1000000 -> -1.7682 | O6: =N6+P$1 -> -4.2
A7: 44658.428 | B7: ah11d1 | C7: 99.999817 | D7: 9.7979589e-08 | E7: 0.0020919 | F7: 9.4339811e-07 | G7: 1591.5 | H7: 15 | J7: =C7-C$3 -> 99.999817 | K7: =E7-E$3 -> 0.00206472 | L7: =K7*0.000000001/(2*PI()*J7*G7*0.000000000001) -> 2.0647879e-06 | M7: 100 | N7: =(J7/M7-1)*1000000 -> -1.8298 | O7: =N7+P$1 -> -4.2616
A8: 44658.429 | B8: ah11a2 | C8: 9.9999758 | D8: 1.0069757e-07 | E8: -0.00025436 | F8: 1.2634872e-06 | G8: 1591.5 | H8: 15 | I8: 11.8, -11.8, 28.7, -.040, -.056, -.010, .025 | J8: =C8-C$3 -> 9.9999758 | K8: =E8-E$3 -> -0.00028154 | L8: =K8*0.000000001/(2*PI()*J8*G8*0.000000000001) -> -2.8154943e-06 | M8: 10 | N8: =(J8/M8-1)*1000000 -> -2.419 | O8: =N8+P$1 -> -4.8508
A9: 44658.431 | B9: ah11b2 | C9: 9.9999731 | D9: 9.9704564e-08 | E9: -0.00021448 | F9: 6.7941151e-07 | G9: 1591.5 | H9: 15 | J9: =C9-C$3 -> 9.9999731 | K9: =E9-E$3 -> -0.00024166 | L9: =K9*0.000000001/(2*PI()*J9*G9*0.000000000001) -> -2.4166816e-06 | M9: 10 | N9: =(J9/M9-1)*1000000 -> -2.6883 | O9: =N9+P$1 -> -5.1201
A10: 44658.433 | B10: ah11c2 | C10: 99.999782 | D10: 9.7979589e-08 | E10: 0.0008197 | F10: 1.3453624e-06 | G10: 1591.5 | H10: 15 | J10: =C10-C$3 -> 99.999782 | K10: =E10-E$3 -> 0.00079252 | L10: =K10*0.000000001/(2*PI()*J10*G10*0.000000000001) -> 7.9254635e-07 | M10: 100 | N10: =(J10/M10-1)*1000000 -> -2.1834 | O10: =N10+P$1 -> -4.6152
A11: 44658.434 | B11: ah11d2 | C11: 99.999866 | D11: 1.2489996e-07 | E11: 0.0009109 | F11: 1.0440307e-06 | G11: 1591.5 | H11: 15 | J11: =C11-C$3 -> 99.999866 | K11: =E11-E$3 -> 0.00088372 | L11: =K11*0.000000001/(2*PI()*J11*G11*0.000000000001) -> 8.8374863e-07 | M11: 100 | N11: =(J11/M11-1)*1000000 -> -1.3414 | O11: =N11+P$1 -> -3.7732
A12: 44658.435 | B12: gr10 | C12: 10.000274 | D12: 2.0880613e-07 | E12: 0.00097426 | F12: 3.5556153e-06 | G12: 1591.5 | H12: 15 | I12: GR inner displays as 25.46 | J12: =C12-C$3 -> 10.000274 | K12: =E12-E$3 -> 0.00094708 | L12: =K12*0.000000001/(2*PI()*J12*G12*0.000000000001) -> 9.4708343e-06 | M12: 10 | N12: =(J12/M12-1)*1000000 -> 27.436 | O12: =N12+P$1 -> 25.0042
A13: 44658.438 | B13: gr100 | C13: 100.0044 | D13: 0 | E13: 0.0089352 | F13: 3.9291857e-05 | G13: 1591.5 | H13: 15 | J13: =C13-C$3 -> 100.0044 | K13: =E13-E$3 -> 0.00890802 | L13: =K13*0.000000001/(2*PI()*J13*G13*0.000000000001) -> 8.9079048e-06 | M13: 100 | N13: =(J13/M13-1)*1000000 -> 43.9904 | O13: =N13+P$1 -> 41.5586
A14: 44658.44 | B14: gr1000a | C14: 1000.0344 | D14: 4.5825757e-06 | E14: 0.200902 | F14: 0.00017514565 | G14: 1591.5 | H14: 1.5 | J14: =C14-C$3 -> 1000.0344 | K14: =E14-E$3 -> 0.20087482 | L14: =K14*0.000000001/(2*PI()*J14*G14*0.000000000001) -> 2.0087415e-05 | M14: 1000 | N14: =(J14/M14-1)*1000000 -> 34.37304 | O14: =N14+P$1 -> 31.94124
A15: 44658.453 | B15: gr1000b | C15: 1000.0186 | D15: 4.5825757e-06 | E15: 0.205152 | F15: 0.00032865788 | G15: 1591.5 | H15: 1.5 | J15: =C15-C$3 -> 1000.0186 | K15: =E15-E$3 -> 0.20512482 | L15: =K15*0.000000001/(2*PI()*J15*G15*0.000000000001) -> 2.0512738e-05 | M15: 1000 | N15: =(J15/M15-1)*1000000 -> 18.57304 | O15: =N15+P$1 -> 16.14124
A16: 44658.455 | B16: es13 | C16: 4.9999472 | D16: 5.9841457e-08 | E16: 0.00025458 | F16: 1.6606023e-06 | G16: 1591.5 | H16: 15 | I16: GMH 526 reads 22.89, (logging shows 24.00??_not likely) | J16: =C16-C$3 -> 4.9999472 | K16: =E16-E$3 -> 0.0002274 | L16: =K16*0.000000001/(2*PI()*J16*G16*0.000000000001) -> 4.5481892e-06 | M16: 5 | N16: =(J16/M16-1)*1000000 -> -10.5514 | O16: =N16+P$1 -> -12.9832
A17: 44658.458 | B17: es16 | C17: 5.0000961 | D17: 7.4458042e-08 | E17: 0.00020051 | F17: 8.1908486e-07 | G17: 1591.5 | H17: 15 | I17: GMH reads 22.89 | J17: =C17-C$3 -> 5.0000961 | K17: =E17-E$3 -> 0.00017333 | L17: =K17*0.000000001/(2*PI()*J17*G17*0.000000000001) -> 3.466641e-06 | M17: 5 | N17: =(J17/M17-1)*1000000 -> 19.2292 | O17: =N17+P$1 -> 16.7974
A18: 44658.46 | B18: es14 | C18: 0.50005064 | D18: 9.5084173e-08 | E18: 7.655e-05 | F18: 5.85235e-07 | G18: 1591.5 | H18: 15 | I18: GMh526 reads 22.89 | J18: =C18-C$3 -> 0.50005068 | K18: =E18-E$3 -> 4.937e-05 | L18: =K18*0.000000001/(2*PI()*J18*G18*0.000000000001) -> 9.873306e-06 | M18: 0.5 | N18: =(J18/M18-1)*1000000 -> 101.354 | O18: =N18+P$1 -> 98.9222
A19: 44658.465 | B19: ub1000 | C19: 1000.1665 | D19: 4.8989795e-06 | E19: 0.213109 | F19: 0.00087788895 | G19: 1591.5 | H19: 1.5 | I19: Black labelled leads for GR connectors, GMH reads 21.29 and falling, 1019.94 mb, RH 55.2, GMH now 21.09 | J19: =C19-C$3 -> 1000.1665 | K19: =E19-E$3 -> 0.21308182 | L19: =K19*0.000000001/(2*PI()*J19*G19*0.000000000001) -> 2.1305297e-05 | M19: 1000 | N19: =(J19/M19-1)*1000000 -> 166.47604 | O19: =N19+P$1 -> 164.04424
A20: 44658.539 | B20: PC1 | C20: 10.000389 | D20: 1.0954451e-07 | E20: 0.00048367 | F20: 1.6309813e-06 | G20: 1591.5 | H20: 15 | I20: Lead B to HV, Lead A to detector, A side shorted, GHM reads 23.33, logging reads 24, note the Sball is 23.0 on logging! | J20: =C20-C$3 -> 10.000389 | K20: =E20-E$3 -> 0.00045649 | L20: =K20*0.000000001/(2*PI()*J20*G20*0.000000000001) -> 4.5648642e-06 | M20: 10 | N20: =(J20/M20-1)*1000000 -> 38.894 | O20: =N20+P$1 -> 36.4622
A21: 44658.542 | B21: PC2 | C21: 10.000152 | D21: 1.3747727e-07 | E21: 0.00048675 | F21: 5.8411043e-06 | G21: 1591.5 | H21: 15 | J21: =C21-C$3 -> 10.000152 | K21: =E21-E$3 -> 0.00045957 | L21: =K21*0.000000001/(2*PI()*J21*G21*0.000000000001) -> 4.5957731e-06 | M21: 10 | N21: =(J21/M21-1)*1000000 -> 15.163 | O21: =N21+P$1 -> 12.7312
A22: 44658.543 | B22: PC3 | C22: 10.000126 | D22: 1.0198039e-07 | E22: 0.00046229 | F22: 2.5339495e-06 | G22: 1591.5 | H22: 15 | J22: =C22-C$3 -> 10.000126 | K22: =E22-E$3 -> 0.00043511 | L22: =K22*0.000000001/(2*PI()*J22*G22*0.000000000001) -> 4.3511804e-06 | M22: 10 | N22: =(J22/M22-1)*1000000 -> 12.58 | O22: =N22+P$1 -> 10.1482
A23: 44658.544 | B23: PC4 | C23: 10.000231 | D23: 1.6763055e-07 | E23: 0.00049855 | F23: 2.1731314e-06 | G23: 1591.5 | H23: 15 | J23: =C23-C$3 -> 10.000231 | K23: =E23-E$3 -> 0.00047137 | L23: =K23*0.000000001/(2*PI()*J23*G23*0.000000000001) -> 4.7137375e-06 | M23: 10 | N23: =(J23/M23-1)*1000000 -> 23.101 | O23: =N23+P$1 -> 20.6692
A24: 44658.544 | B24: PC5 | C24: 9.9999945 | D24: 1.4379152e-07 | E24: 0.00046881 | F24: 1.6501212e-06 | G24: 1591.5 | H24: 15 | J24: =C24-C$3 -> 9.9999945 | K24: =E24-E$3 -> 0.00044163 | L24: =K24*0.000000001/(2*PI()*J24*G24*0.000000000001) -> 4.4164396e-06 | M24: 10 | N24: =(J24/M24-1)*1000000 -> -0.5478 | O24: =N24+P$1 -> -2.9796
A25: 44658.545 | B25: PC6 | C25: 10.000239 | D25: 8.3066239e-08 | E25: 0.00050214 | F25: 2.7317394e-06 | G25: 1591.5 | H25: 15 | J25: =C25-C$3 -> 10.000239 | K25: =E25-E$3 -> 0.00047496 | L25: =K25*0.000000001/(2*PI()*J25*G25*0.000000000001) -> 4.7496341e-06 | M25: 10 | N25: =(J25/M25-1)*1000000 -> 23.885 | O25: =N25+P$1 -> 21.4532
A26: 44658.548 | B26: PC7 | C26: 10.000323 | D26: 9.4339811e-08 | E26: 0.00049333 | F26: 3.4008969e-06 | G26: 1591.5 | H26: 15 | I26: GMH526 reads 23.33 | J26: =C26-C$3 -> 10.000323 | K26: =E26-E$3 -> 0.00046615 | L26: =K26*0.000000001/(2*PI()*J26*G26*0.000000000001) -> 4.6614944e-06 | M26: 10 | N26: =(J26/M26-1)*1000000 -> 32.255 | O26: =N26+P$1 -> 29.8232
A27: 44658.549 | B27: PC8 | C27: 10.000252 | D27: 1.0049876e-07 | E27: 0.00048324 | F27: 1.9147846e-06 | G27: 1591.5 | H27: 15 | J27: =C27-C$3 -> 10.000252 | K27: =E27-E$3 -> 0.00045606 | L27: =K27*0.000000001/(2*PI()*J27*G27*0.000000000001) -> 4.5606266e-06 | M27: 10 | N27: =(J27/M27-1)*1000000 -> 25.217 | O27: =N27+P$1 -> 22.7852
A28: 44658.55 | B28: PC9 | C28: 10.000381 | D28: 1.5620499e-07 | E28: 0.00049233 | F28: 1.7550214e-06 | G28: 1591.5 | H28: 15 | J28: =C28-C$3 -> 10.000381 | K28: =E28-E$3 -> 0.00046515 | L28: =K28*0.000000001/(2*PI()*J28*G28*0.000000000001) -> 4.6514673e-06 | M28: 10 | N28: =(J28/M28-1)*1000000 -> 38.08 | O28: =N28+P$1 -> 35.6482
A29: 44658.551 | B29: PC10 | C29: 10.000413 | D29: 1.7349352e-07 | E29: 0.00048229 | F29: 1.4081548e-06 | G29: 1591.5 | H29: 15 | J29: =C29-C$3 -> 10.000413 | K29: =E29-E$3 -> 0.00045511 | L29: =K29*0.000000001/(2*PI()*J29*G29*0.000000000001) -> 4.5510534e-06 | M29: 10 | N29: =(J29/M29-1)*1000000 -> 41.297 | O29: =N29+P$1 -> 38.8652
A30: 44658.552 | B30: PC11 | C30: 10.000236 | D30: 1.5362292e-07 | E30: 0.00047382 | F30: 1.721511e-06 | G30: 1591.5 | H30: 15 | I30: GMH 23.33, 1020.73 mb, 55.0% RH | J30: =C30-C$3 -> 10.000236 | K30: =E30-E$3 -> 0.00044664 | L30: =K30*0.000000001/(2*PI()*J30*G30*0.000000000001) -> 4.4664333e-06 | M30: 10 | N30: =(J30/M30-1)*1000000 -> 23.612 | O30: =N30+P$1 -> 21.1802

Sheet AH2700A2022-04-11
A1: av_exp = 10, frequency = 1591.5, no. of samples = 10, settling samples = 2 | J1: zero_corrected | K1: from G:\Shared drives\MSL - Electricity - Ongoing\Farad\Cap_Scale_Sept_2021\compare 2019 2020.xlsx cell AA30 | M1: AH11C1 | N1: -4.2 | O1: correction | P1: =N1 - N6 -> -2.42937
A2: DateTime | B2: Capacitor | C2: Capacitance (pF) | D2: uCap (pF) | E2: Conductance (nS) | F2: uCond (nS) | G2: Frequency (Hz) | H2: Voltage (V) | J2: Capacitance (pF) | K2: Conductance (nS) | L2: tand | M2: nominal C | N2: error | O2: corrected ppm
A3: 44662.409 | B3: zero | C3: -8.7e-08 | D3: 8.6029065e-08 | E3: 2.672e-05 | F3: 9.2065194e-07 | G3: 1591.5 | H3: 15 | I3: AH2 long leads, 1021.35 mb, 20.6 deg, 56.2 % RH | J3: =C3-C$3 -> 0 | K3: =D3-D$3 -> 0 | L3: - | N3: ppm
A4: 44662.411 | B4: ah11a1 | C4: 9.9999756 | D4: 6.8731361e-08 | E4: -0.00015854 | F4: 1.2792185e-06 | G4: 1591.5 | H4: 15 | I4: 11.9, -11.7, 29.0, .034, -.017, -.012 | J4: =C4-C$3 -> 9.9999757 | K4: =E4-E$3 -> -0.00018526 | L4: =K4*0.000000001/(2*PI()*J4*G4*0.000000000001) -> -1.852662e-06 | M4: 10 | N4: =(J4/M4-1)*1000000 -> -2.4267 | O4: =N4+P$1 -> -4.85607
A5: 44662.413 | B5: ah11b1 | C5: 9.9999781 | D5: 1.1304866e-07 | E5: -9.842e-05 | F5: 9.2822411e-07 | G5: 1591.5 | H5: 15 | I5: and the last one is 0.021 | J5: =C5-C$3 -> 9.9999782 | K5: =E5-E$3 -> -0.00012514 | L5: =K5*0.000000001/(2*PI()*J5*G5*0.000000000001) -> -1.2514416e-06 | M5: 10 | N5: =(J5/M5-1)*1000000 -> -2.1803 | O5: =N5+P$1 -> -4.60967
A6: 44662.414 | B6: ah11c1 | C6: 99.999823 | D6: 1.5e-07 | E6: 0.0017088 | F6: 2.5612497e-06 | G6: 1591.5 | H6: 15 | J6: =C6-C$3 -> 99.999823 | K6: =E6-E$3 -> 0.00168208 | L6: =K6*0.000000001/(2*PI()*J6*G6*0.000000000001) -> 1.6821352e-06 | M6: 100 | N6: =(J6/M6-1)*1000000 -> -1.77063 | O6: =N6+P$1 -> -4.2
A7: 44662.415 | B7: ah11d1 | C7: 99.999817 | D7: 7.8102497e-08 | E7: 0.0020879 | F7: 1.4456832e-06 | G7: 1591.5 | H7: 15 | J7: =C7-C$3 -> 99.999817 | K7: =E7-E$3 -> 0.00206118 | L7: =K7*0.000000001/(2*PI()*J7*G7*0.000000000001) -> 2.0612478e-06 | M7: 100 | N7: =(J7/M7-1)*1000000 -> -1.83083 | O7: =N7+P$1 -> -4.2602
A8: 44662.438 | B8: ah11a2 | C8: 9.9999755 | D8: 1.3131641e-07 | E8: -0.00025619 | F8: 8.3360662e-07 | G8: 1591.5 | H8: 15 | I8: 11.8, -11.9, -.040, -.056, -.011, .024 | J8: =C8-C$3 -> 9.9999756 | K8: =E8-E$3 -> -0.00028291 | L8: =K8*0.000000001/(2*PI()*J8*G8*0.000000000001) -> -2.8291948e-06 | M8: 10 | N8: =(J8/M8-1)*1000000 -> -2.4427 | O8: =N8+P$1 -> -4.87207
A9: 44662.44 | B9: ah11b2 | C9: 9.999973 | D9: 6.3725976e-08 | E9: -0.0002234 | F9: 9.5498691e-07 | G9: 1591.5 | H9: 15 | J9: =C9-C$3 -> 9.9999731 | K9: =E9-E$3 -> -0.00025012 | L9: =K9*0.000000001/(2*PI()*J9*G9*0.000000000001) -> -2.5012844e-06 | M9: 10 | N9: =(J9/M9-1)*1000000 -> -2.69 | O9: =N9+P$1 -> -5.11937
A10: 44662.441 | B10: ah11c2 | C10: 99.99978 | D10: 1.5132746e-07 | E10: 0.0007991 | F10: 1.8681542e-06 | G10: 1591.5 | H10: 15 | J10: =C10-C$3 -> 99.99978 | K10: =E10-E$3 -> 0.00077238 | L10: =K10*0.000000001/(2*PI()*J10*G10*0.000000000001) -> 7.7240569e-07 | M10: 100 | N10: =(J10/M10-1)*1000000 -> -2.19803 | O10: =N10+P$1 -> -4.6274
A11: 44662.443 | B11: ah11d2 | C11: 99.999862 | D11: 7.4833148e-08 | E11: 0.0008918 | F11: 1.9899749e-06 | G11: 1591.5 | H11: 15 | J11: =C11-C$3 -> 99.999862 | K11: =E11-E$3 -> 0.00086508 | L11: =K11*0.000000001/(2*PI()*J11*G11*0.000000000001) -> 8.6510807e-07 | M11: 100 | N11: =(J11/M11-1)*1000000 -> -1.38333 | O11: =N11+P$1 -> -3.8127
A12: 44662.444 | B12: gr10 | C12: 10.000274 | D12: 1.6401219e-07 | E12: 0.00097077 | F12: 3.74968e-06 | G12: 1591.5 | H12: 15 | I12: GR inner 25.458, 1021.16 mb | J12: =C12-C$3 -> 10.000274 | K12: =E12-E$3 -> 0.00094405 | L12: =K12*0.000000001/(2*PI()*J12*G12*0.000000000001) -> 9.4405348e-06 | M12: 10 | N12: =(J12/M12-1)*1000000 -> 27.3777 | O12: =N12+P$1 -> 24.94833
A13: 44662.446 | B13: gr100 | C13: 100.00439 | D13: 3e-07 | E13: 0.0086802 | F13: 4.2571822e-05 | G13: 1591.5 | H13: 15 | J13: =C13-C$3 -> 100.00439 | K13: =E13-E$3 -> 0.00865348 | L13: =K13*0.000000001/(2*PI()*J13*G13*0.000000000001) -> 8.6533685e-06 | M13: 100 | N13: =(J13/M13-1)*1000000 -> 43.94987 | O13: =N13+P$1 -> 41.5205
A14: 44662.448 | B14: gr1000a | C14: 1000.0343 | D14: 3e-06 | E14: 0.195471 | F14: 0.00017328878 | G14: 1591.5 | H14: 1.5 | J14: =C14-C$3 -> 1000.0343 | K14: =E14-E$3 -> 0.19544428 | L14: =K14*0.000000001/(2*PI()*J14*G14*0.000000000001) -> 1.9544364e-05 | M14: 1000 | N14: =(J14/M14-1)*1000000 -> 34.319087 | O14: =N14+P$1 -> 31.889717
A15: 44662.449 | B15: gr1000b | C15: 1000.0185 | D15: 4.8989795e-06 | E15: 0.200965 | F15: 0.00012060265 | G15: 1591.5 | H15: 1.5 | J15: =C15-C$3 -> 1000.0185 | K15: =E15-E$3 -> 0.20093828 | L15: =K15*0.000000001/(2*PI()*J15*G15*0.000000000001) -> 2.009408e-05 | M15: 1000 | N15: =(J15/M15-1)*1000000 -> 18.534087 | O15: =N15+P$1 -> 16.104717
A16: 44662.451 | B16: es13 | C16: 4.9999474 | D16: 6.9289249e-08 | E16: 0.00025267 | F16: 1.445026e-06 | G16: 1591.5 | H16: 15 | I16: GMH526 22.88, logging 23.295 | J16: =C16-C$3 -> 4.9999475 | K16: =E16-E$3 -> 0.00022595 | L16: =K16*0.000000001/(2*PI()*J16*G16*0.000000000001) -> 4.5191878e-06 | M16: 5 | N16: =(J16/M16-1)*1000000 -> -10.494 | O16: =N16+P$1 -> -12.92337
A17: 44662.453 | B17: es16 | C17: 5.0000966 | D17: 1.161034e-07 | E17: 0.00022521 | F17: 5.1657429e-06 | G17: 1591.5 | H17: 15 | I17: GMH 22.88 | J17: =C17-C$3 -> 5.0000967 | K17: =E17-E$3 -> 0.00019849 | L17: =K17*0.000000001/(2*PI()*J17*G17*0.000000000001) -> 3.9698465e-06 | M17: 5 | N17: =(J17/M17-1)*1000000 -> 19.3394 | O17: =N17+P$1 -> 16.91003
A18: 44662.455 | B18: es14 | C18: 0.5000506 | D18: 6.4226163e-08 | E18: 7.374e-05 | F18: 1.5067847e-06 | G18: 1591.5 | H18: 15 | I18: GMH 22.87 | J18: =C18-C$3 -> 0.50005068 | K18: =E18-E$3 -> 4.702e-05 | L18: =K18*0.000000001/(2*PI()*J18*G18*0.000000000001) -> 9.4033389e-06 | M18: 0.5 | N18: =(J18/M18-1)*1000000 -> 101.364 | O18: =N18+P$1 -> 98.93463
A19: 44662.462 | B19: ub1000 | C19: 1000.1675 | D19: 6.4031242e-06 | E19: 0.256899 | F19: 0.00044347379 | G19: 1591.5 | H19: 1.5 | I19: GMH526 20.72, 1021.26 mb, 56.9% | J19: =C19-C$3 -> 1000.1675 | K19: =E19-E$3 -> 0.25687228 | L19: =K19*0.000000001/(2*PI()*J19*G19*0.000000000001) -> 2.5683724e-05 | M19: 1000 | N19: =(J19/M19-1)*1000000 -> 167.49309 | O19: =N19+P$1 -> 165.06372
A20: 44662.466 | B20: PC1 | C20: 10.00039 | D20: 1.3747727e-07 | E20: 0.00048357 | F20: 2.3732046e-06 | G20: 1591.5 | H20: 15 | I20: GMH 23.34, logging 23.995 | J20: =C20-C$3 -> 10.00039 | K20: =E20-E$3 -> 0.00045685 | L20: =K20*0.000000001/(2*PI()*J20*G20*0.000000000001) -> 4.5684636e-06 | M20: 10 | N20: =(J20/M20-1)*1000000 -> 39.0177 | O20: =N20+P$1 -> 36.58833
A21: 44662.468 | B21: PC2 | C21: 10.000153 | D21: 1.2041595e-07 | E21: 0.00048112 | F21: 2.3314373e-06 | G21: 1591.5 | H21: 15 | J21: =C21-C$3 -> 10.000153 | K21: =E21-E$3 -> 0.0004544 | L21: =K21*0.000000001/(2*PI()*J21*G21*0.000000000001) -> 4.5440717e-06 | M21: 10 | N21: =(J21/M21-1)*1000000 -> 15.2837 | O21: =N21+P$1 -> 12.85433
A22: 44662.469 | B22: PC3 | C22: 10.000127 | D22: 1.2688578e-07 | E22: 0.00046995 | F22: 3.3856314e-06 | G22: 1591.5 | H22: 15 | J22: =C22-C$3 -> 10.000127 | K22: =E22-E$3 -> 0.00044323 | L22: =K22*0.000000001/(2*PI()*J22*G22*0.000000000001) -> 4.4323813e-06 | M22: 10 | N22: =(J22/M22-1)*1000000 -> 12.7217 | O22: =N22+P$1 -> 10.29233
A23: 44662.47 | B23: PC4 | C23: 10.000232 | D23: 1.4696938e-07 | E23: 0.00050553 | F23: 3.0551759e-06 | G23: 1591.5 | H23: 15 | J23: =C23-C$3 -> 10.000232 | K23: =E23-E$3 -> 0.00047881 | L23: =K23*0.000000001/(2*PI()*J23*G23*0.000000000001) -> 4.7881374e-06 | M23: 10 | N23: =(J23/M23-1)*1000000 -> 23.2467 | O23: =N23+P$1 -> 20.81733
A24: 44662.472 | B24: PC5 | C24: 9.9999957 | D24: 1.2562245e-07 | E24: 0.00047259 | F24: 3.0703257e-06 | G24: 1591.5 | H24: 15 | J24: =C24-C$3 -> 9.9999958 | K24: =E24-E$3 -> 0.00044587 | L24: =K24*0.000000001/(2*PI()*J24*G24*0.000000000001) -> 4.4588404e-06 | M24: 10 | N24: =(J24/M24-1)*1000000 -> -0.421 | O24: =N24+P$1 -> -2.85037
A25: 44662.472 | B25: PC6 | C25: 10.00024 | D25: 1.4142136e-07 | E25: 0.00050421 | F25: 2.3851415e-06 | G25: 1591.5 | H25: 15 | J25: =C25-C$3 -> 10.00024 | K25: =E25-E$3 -> 0.00047749 | L25: =K25*0.000000001/(2*PI()*J25*G25*0.000000000001) -> 4.7749336e-06 | M25: 10 | N25: =(J25/M25-1)*1000000 -> 24.0287 | O25: =N25+P$1 -> 21.59933
A26: 44662.473 | B26: PC7 | C26: 10.000324 | D26: 1.7776389e-07 | E26: 0.000502 | F26: 2.99366e-06 | G26: 1591.5 | H26: 15 | J26: =C26-C$3 -> 10.000324 | K26: =E26-E$3 -> 0.00047528 | L26: =K26*0.000000001/(2*PI()*J26*G26*0.000000000001) -> 4.7527936e-06 | M26: 10 | N26: =(J26/M26-1)*1000000 -> 32.4007 | O26: =N26+P$1 -> 29.97133
A27: 44662.474 | B27: PC8 | C27: 10.000254 | D27: 8.9442719e-08 | E27: 0.00049493 | F27: 2.0169531e-06 | G27: 1591.5 | H27: 15 | I27: GMH 23.34 | J27: =C27-C$3 -> 10.000254 | K27: =E27-E$3 -> 0.00046821 | L27: =K27*0.000000001/(2*PI()*J27*G27*0.000000000001) -> 4.6821266e-06 | M27: 10 | N27: =(J27/M27-1)*1000000 -> 25.3787 | O27: =N27+P$1 -> 22.94933
A28: 44662.475 | B28: PC9 | C28: 10.000382 | D28: 1e-07 | E28: 0.00050181 | F28: 3.0319796e-06 | G28: 1591.5 | H28: 15 | J28: =C28-C$3 -> 10.000382 | K28: =E28-E$3 -> 0.00047509 | L28: =K28*0.000000001/(2*PI()*J28*G28*0.000000000001) -> 4.7508659e-06 | M28: 10 | N28: =(J28/M28-1)*1000000 -> 38.2287 | O28: =N28+P$1 -> 35.79933
A29: 44662.476 | B29: PC10 | C29: 10.000415 | D29: 1.2489996e-07 | E29: 0.0004911 | F29: 2.466982e-06 | G29: 1591.5 | H29: 15 | J29: =C29-C$3 -> 10.000415 | K29: =E29-E$3 -> 0.00046438 | L29: =K29*0.000000001/(2*PI()*J29*G29*0.000000000001) -> 4.6437517e-06 | M29: 10 | N29: =(J29/M29-1)*1000000 -> 41.4667 | O29: =N29+P$1 -> 39.03733
A30: 44662.477 | B30: PC11 | C30: 10.000238 | D30: 1.5132746e-07 | E30: 0.00048478 | F30: 2.4334338e-06 | G30: 1591.5 | H30: 15 | J30: =C30-C$3 -> 10.000238 | K30: =E30-E$3 -> 0.00045806 | L30: =K30*0.000000001/(2*PI()*J30*G30*0.000000000001) -> 4.5806334e-06 | M30: 10 | N30: =(J30/M30-1)*1000000 -> 23.7597 | O30: =N30+P$1 -> 21.33033

Sheet AH2700A2022-05-30
A1: av_exp = 10, frequency = 1591.5, no. of samples = 10, settling samples = 2 | J1: zero_corrected | K1: from G:\Shared drives\MSL - Electricity - Ongoing\Farad\Cap_Scale_Sept_2021\compare 2019 2020.xlsx cell AA30 | M1: AH11C1 | N1: -4.2 | O1: correction | P1: =N1 - N6 -> -2.42688
A2: DateTime | B2: Capacitor | C2: Capacitance (pF) | D2: uCap (pF) | E2: Conductance (nS) | F2: uCond (nS) | G2: Frequency (Hz) | H2: Voltage (V) | J2: Capacitance (pF) | K2: Conductance (nS) | L2: tand | M2: nominal C | N2: error | O2: corrected ppm
A3: 44711.548 | B3: zero | C3: -1.38e-07 | D3: 6.3055531e-08 | E3: 2.819e-05 | F3: 4.7423623e-07 | G3: 1591.5 | H3: 15 | I3: FCU08 20.66, 49.62 %. AH11_1: 11.9, -11.7, 31.2, .033, -.016, -.010, .016 | J3: =C3-C$3 -> 0 | K3: =D3-D$3 -> 0 | L3: - | N3: ppm
A4: 44711.551 | B4: ah11a1 | C4: 9.9999762 | D4: 9.0553851e-08 | E4: -8.565e-05 | F4: 9.0138782e-07 | G4: 1591.5 | H4: 15 | I4: pressure 1006.48 mb | J4: =C4-C$3 -> 9.9999763 | K4: =E4-E$3 -> -0.00011384 | L4: =K4*0.000000001/(2*PI()*J4*G4*0.000000000001) -> -1.1384381e-06 | M4: 10 | N4: =(J4/M4-1)*1000000 -> -2.3672 | O4: =N4+P$1 -> -4.79408
A5: 44711.552 | B5: ah11b1 | C5: 9.9999781 | D5: 7.0859015e-08 | E5: 2.34e-06 | F5: 1.037497e-06 | G5: 1591.5 | H5: 15 | J5: =C5-C$3 -> 9.9999782 | K5: =E5-E$3 -> -2.585e-05 | L5: =K5*0.000000001/(2*PI()*J5*G5*0.000000000001) -> -2.5850859e-07 | M5: 10 | N5: =(J5/M5-1)*1000000 -> -2.1795 | O5: =N5+P$1 -> -4.60638
A6: 44711.553 | B6: ah11c1 | C6: 99.999823 | D6: 8.0622579e-08 | E6: 0.0017922 | F6: 9.797959e-07 | G6: 1591.5 | H6: 15 | J6: =C6-C$3 -> 99.999823 | K6: =E6-E$3 -> 0.00176401 | L6: =K6*0.000000001/(2*PI()*J6*G6*0.000000000001) -> 1.7640679e-06 | M6: 100 | N6: =(J6/M6-1)*1000000 -> -1.77312 | O6: =N6+P$1 -> -4.2
A7: 44711.554 | B7: ah11d1 | C7: 99.999817 | D7: 8.3066239e-08 | E7: 0.0021574 | F7: 1.0198039e-06 | G7: 1591.5 | H7: 15 | I7: AH112: 11.8, -11.9, 30.2, -.033, -.046, -.003, .022 | J7: =C7-C$3 -> 99.999817 | K7: =E7-E$3 -> 0.00212921 | L7: =K7*0.000000001/(2*PI()*J7*G7*0.000000000001) -> 2.12928e-06 | M7: 100 | N7: =(J7/M7-1)*1000000 -> -1.82672 | O7: =N7+P$1 -> -4.2536
A8: 44711.556 | B8: ah11a2 | C8: 9.9999758 | D8: 1.0705606e-07 | E8: -0.00021189 | F8: 5.0289164e-07 | G8: 1591.5 | H8: 15 | J8: =C8-C$3 -> 9.9999759 | K8: =E8-E$3 -> -0.00024008 | L8: =K8*0.000000001/(2*PI()*J8*G8*0.000000000001) -> -2.4008803e-06 | M8: 10 | N8: =(J8/M8-1)*1000000 -> -2.4065 | O8: =N8+P$1 -> -4.83338
A9: 44711.557 | B9: ah11b2 | C9: 9.9999733 | D9: 8.7091905e-08 | E9: -0.00017939 | F9: 9.0493094e-07 | G9: 1591.5 | H9: 15 | J9: =C9-C$3 -> 9.9999735 | K9: =E9-E$3 -> -0.00020758 | L9: =K9*0.000000001/(2*PI()*J9*G9*0.000000000001) -> -2.07587e-06 | M9: 10 | N9: =(J9/M9-1)*1000000 -> -2.6547 | O9: =N9+P$1 -> -5.08158
A10: 44711.558 | B10: ah11c2 | C10: 99.999782 | D10: 1.2806248e-07 | E10: 0.0008549 | F10: 1.0440307e-06 | G10: 1591.5 | H10: 15 | J10: =C10-C$3 -> 99.999782 | K10: =E10-E$3 -> 0.00082671 | L10: =K10*0.000000001/(2*PI()*J10*G10*0.000000000001) -> 8.2673748e-07 | M10: 100 | N10: =(J10/M10-1)*1000000 -> -2.18102 | O10: =N10+P$1 -> -4.6079
A11: 44711.559 | B11: ah11d2 | C11: 99.999856 | D11: 9.2195445e-08 | E11: 0.0009438 | F11: 1.1661904e-06 | G11: 1591.5 | H11: 15 | J11: =C11-C$3 -> 99.999857 | K11: =E11-E$3 -> 0.00091561 | L11: =K11*0.000000001/(2*PI()*J11*G11*0.000000000001) -> 9.1563975e-07 | M11: 100 | N11: =(J11/M11-1)*1000000 -> -1.43412 | O11: =N11+P$1 -> -3.861
A12: 44711.561 | B12: gr10 | C12: 10.00007 | D12: 9.2195444e-08 | E12: 0.00084671 | F12: 6.9921384e-07 | G12: 1591.5 | H12: 15 | I12: GR inner 21.122, pressure 1005.93 mb | J12: =C12-C$3 -> 10.00007 | K12: =E12-E$3 -> 0.00081852 | L12: =K12*0.000000001/(2*PI()*J12*G12*0.000000000001) -> 8.1853969e-06 | M12: 10 | N12: =(J12/M12-1)*1000000 -> 6.9988 | O12: =N12+P$1 -> 4.57192
A13: 44711.564 | B13: gr100 | C13: 100.00343 | D13: 0 | E13: 0.0067564 | F13: 1.68523e-06 | G13: 1591.5 | H13: 15 | J13: =C13-C$3 -> 100.00343 | K13: =E13-E$3 -> 0.00672821 | L13: =K13*0.000000001/(2*PI()*J13*G13*0.000000000001) -> 6.7281883e-06 | M13: 100 | N13: =(J13/M13-1)*1000000 -> 34.29138 | O13: =N13+P$1 -> 31.8645
A14: 44711.565 | B14: gr1000a | C14: 1000.0282 | D14: 5e-06 | E14: 0.148574 | F14: 2.8e-05 | G14: 1591.5 | H14: 1.5 | J14: =C14-C$3 -> 1000.0282 | K14: =E14-E$3 -> 0.14854581 | L14: =K14*0.000000001/(2*PI()*J14*G14*0.000000000001) -> 1.4854623e-05 | M14: 1000 | N14: =(J14/M14-1)*1000000 -> 28.235138 | O14: =N14+P$1 -> 25.808258
A15: 44711.567 | B15: gr1000b | C15: 1000.0121 | D15: 5e-06 | E15: 0.153162 | F15: 2.521904e-05 | G15: 1591.5 | H15: 1.5 | I15: GR inner 21.123, pressure 1005.44 mb | J15: =C15-C$3 -> 1000.0121 | K15: =E15-E$3 -> 0.15313381 | L15: =K15*0.000000001/(2*PI()*J15*G15*0.000000000001) -> 1.5313671e-05 | M15: 1000 | N15: =(J15/M15-1)*1000000 -> 12.105138 | O15: =N15+P$1 -> 9.678258
A16: 44711.569 | B16: es13 | C16: 4.9999169 | D16: 9.8386991e-08 | E16: 0.00019832 | F16: 6.0133186e-07 | G16: 1591.5 | H16: 15 | I16: Sapphire ball 21.655 | J16: =C16-C$3 -> 4.999917 | K16: =E16-E$3 -> 0.00017013 | L16: =K16*0.000000001/(2*PI()*J16*G16*0.000000000001) -> 3.4027621e-06 | M16: 5 | N16: =(J16/M16-1)*1000000 -> -16.5904 | O16: =N16+P$1 -> -19.01728
A17: 44711.571 | B17: es16 | C17: 5.0000732 | D17: 8.2758685e-08 | E17: 0.00014668 | F17: 2.4579666e-06 | G17: 1591.5 | H17: 15 | J17: =C17-C$3 -> 5.0000733 | K17: =E17-E$3 -> 0.00011849 | L17: =K17*0.000000001/(2*PI()*J17*G17*0.000000000001) -> 2.3698389e-06 | M17: 5 | N17: =(J17/M17-1)*1000000 -> 14.6638 | O17: =N17+P$1 -> 12.23692
A18: 44711.572 | B18: es14 | C18: 0.50004637 | D18: 1.00005e-07 | E18: 7.444e-05 | F18: 7.5392307e-07 | G18: 1591.5 | H18: 15 | I18: Sapphire ball 21.655 | J18: =C18-C$3 -> 0.5000465 | K18: =E18-E$3 -> 4.625e-05 | L18: =K18*0.000000001/(2*PI()*J18*G18*0.000000000001) -> 9.249427e-06 | M18: 0.5 | N18: =(J18/M18-1)*1000000 -> 93.01 | O18: =N18+P$1 -> 90.58312
A19: 44711.574 | B19: ub1000 | C19: 1000.1498 | D19: 4.8989795e-06 | E19: 0.141179 | F19: 3.6455452e-05 | G19: 1591.5 | H19: 1.5 | I19: GMH 526 under UB1000 reads 20.68, pressure 1005.75 mb | J19: =C19-C$3 -> 1000.1498 | K19: =E19-E$3 -> 0.14115081 | L19: =K19*0.000000001/(2*PI()*J19*G19*0.000000000001) -> 1.4113405e-05 | M19: 1000 | N19: =(J19/M19-1)*1000000 -> 149.83614 | O19: =N19+P$1 -> 147.40926

Sheet AH2700A2022-05-31
A1: av_exp = 10, frequency = 1591.5, no. of samples = 10, settling samples = 2 | J1: zero_corrected | K1: from G:\Shared drives\MSL - Electricity - Ongoing\Farad\Cap_Scale_Sept_2021\compare 2019 2020.xlsx cell AA30 | M1: AH11C1 | N1: -4.2 | O1: correction | P1: =N1 - N6 -> -2.41414
A2: DateTime | B2: Capacitor | C2: Capacitance (pF) | D2: uCap (pF) | E2: Conductance (nS) | F2: uCond (nS) | G2: Frequency (Hz) | H2: Voltage (V) | J2: Capacitance (pF) | K2: Conductance (nS) | L2: tand | M2: nominal C | N2: error | O2: corrected ppm
A3: 44712.462 | B3: zero | C3: 4.66e-07 | D3: 1.1226754e-07 | E3: 2.715e-05 | F3: 6.264982e-07 | G3: 1591.5 | H3: 15 | I3: Fcu08 20.6, 52.99%, AH11_1: 11.9, -11.7, 31.0, .033, -.016, -.010, .017 | J3: =C3-C$3 -> 0 | K3: =D3-D$3 -> 0 | L3: - | N3: ppm
A4: 44712.465 | B4: ah11a1 | C4: 9.9999759 | D4: 1.3456968e-07 | E4: -9.499e-05 | F4: 8.4787971e-07 | G4: 1591.5 | H4: 15 | J4: =C4-C$3 -> 9.9999754 | K4: =E4-E$3 -> -0.00012214 | L4: =K4*0.000000001/(2*PI()*J4*G4*0.000000000001) -> -1.2214409e-06 | M4: 10 | N4: =(J4/M4-1)*1000000 -> -2.4597 | O4: =N4+P$1 -> -4.87384
A5: 44712.466 | B5: ah11b1 | C5: 9.999978 | D5: 8.6075548e-08 | E5: -1.908e-05 | F5: 9.2498649e-07 | G5: 1591.5 | H5: 15 | J5: =C5-C$3 -> 9.9999776 | K5: =E5-E$3 -> -4.623e-05 | L5: =K5*0.000000001/(2*PI()*J5*G5*0.000000000001) -> -4.623154e-07 | M5: 10 | N5: =(J5/M5-1)*1000000 -> -2.2447 | O5: =N5+P$1 -> -4.65884
A6: 44712.467 | B6: ah11c1 | C6: 99.999822 | D6: 1.077033e-07 | E6: 0.001791 | F6: 6.3245553e-07 | G6: 1591.5 | H6: 15 | I6: pressure 1003.76 mb | J6: =C6-C$3 -> 99.999821 | K6: =E6-E$3 -> 0.00176385 | L6: =K6*0.000000001/(2*PI()*J6*G6*0.000000000001) -> 1.7639079e-06 | M6: 100 | N6: =(J6/M6-1)*1000000 -> -1.78586 | O6: =N6+P$1 -> -4.2
A7: 44712.468 | B7: ah11d1 | C7: 99.999816 | D7: 1.3416408e-07 | E7: 0.0021646 | F7: 1.2806248e-06 | G7: 1591.5 | H7: 15 | I7: AH11_2: 11.8, -11.9, 30.1, -.033, -.047, -.004, .022 | J7: =C7-C$3 -> 99.999816 | K7: =E7-E$3 -> 0.00213745 | L7: =K7*0.000000001/(2*PI()*J7*G7*0.000000000001) -> 2.1375203e-06 | M7: 100 | N7: =(J7/M7-1)*1000000 -> -1.83966 | O7: =N7+P$1 -> -4.2538
A8: 44712.47 | B8: ah11a2 | C8: 9.9999756 | D8: 1.6555664e-07 | E8: -0.00020186 | F8: 8.3689904e-07 | G8: 1591.5 | H8: 15 | J8: =C8-C$3 -> 9.9999752 | K8: =E8-E$3 -> -0.00022901 | L8: =K8*0.000000001/(2*PI()*J8*G8*0.000000000001) -> -2.2901768e-06 | M8: 10 | N8: =(J8/M8-1)*1000000 -> -2.4827 | O8: =N8+P$1 -> -4.89684
A9: 44712.471 | B9: ah11b2 | C9: 9.9999732 | D9: 1.0030454e-07 | E9: -0.00016134 | F9: 6.8e-07 | G9: 1591.5 | H9: 15 | J9: =C9-C$3 -> 9.9999727 | K9: =E9-E$3 -> -0.00018849 | L9: =K9*0.000000001/(2*PI()*J9*G9*0.000000000001) -> -1.8849637e-06 | M9: 10 | N9: =(J9/M9-1)*1000000 -> -2.7299 | O9: =N9+P$1 -> -5.14404
A10: 44712.472 | B10: ah11c2 | C10: 99.999781 | D10: 8.3066237e-08 | E10: 0.0008771 | F10: 8.3066239e-07 | G10: 1591.5 | H10: 15 | J10: =C10-C$3 -> 99.999781 | K10: =E10-E$3 -> 0.00084995 | L10: =K10*0.000000001/(2*PI()*J10*G10*0.000000000001) -> 8.4997826e-07 | M10: 100 | N10: =(J10/M10-1)*1000000 -> -2.19356 | O10: =N10+P$1 -> -4.6077
A11: 44712.473 | B11: ah11d2 | C11: 99.999857 | D11: 5.385165e-08 | E11: 0.0009661 | F11: 1.1357817e-06 | G11: 1591.5 | H11: 15 | J11: =C11-C$3 -> 99.999857 | K11: =E11-E$3 -> 0.00093895 | L11: =K11*0.000000001/(2*PI()*J11*G11*0.000000000001) -> 9.3898051e-07 | M11: 100 | N11: =(J11/M11-1)*1000000 -> -1.43476 | O11: =N11+P$1 -> -3.8489
A12: 44712.476 | B12: gr10 | C12: 10.000211 | D12: 9.4339811e-08 | E12: 0.00086934 | F12: 1.109234e-06 | G12: 1591.5 | H12: 15 | I12: pressure 1003.64 mb, GR outer 23.98 | J12: =C12-C$3 -> 10.00021 | K12: =E12-E$3 -> 0.00084219 | L12: =K12*0.000000001/(2*PI()*J12*G12*0.000000000001) -> 8.4219846e-06 | M12: 10 | N12: =(J12/M12-1)*1000000 -> 21.0144 | O12: =N12+P$1 -> 18.60026
A13: 44712.479 | B13: gr100 | C13: 100.00409 | D13: 0 | E13: 0.0071302 | F13: 2.0099751e-06 | G13: 1591.5 | H13: 15 | I13: GR inner 23.98 | J13: =C13-C$3 -> 100.00409 | K13: =E13-E$3 -> 0.00710305 | L13: =K13*0.000000001/(2*PI()*J13*G13*0.000000000001) -> 7.1029801e-06 | M13: 100 | N13: =(J13/M13-1)*1000000 -> 40.90534 | O13: =N13+P$1 -> 38.4912
A14: 44712.481 | B14: gr1000a | C14: 1000.0324 | D14: 3e-06 | E14: 0.159852 | F14: 2.2715633e-05 | G14: 1591.5 | H14: 1.5 | J14: =C14-C$3 -> 1000.0324 | K14: =E14-E$3 -> 0.15982485 | L14: =K14*0.000000001/(2*PI()*J14*G14*0.000000000001) -> 1.5982463e-05 | M14: 1000 | N14: =(J14/M14-1)*1000000 -> 32.428534 | O14: =N14+P$1 -> 30.014394
A15: 44712.482 | B15: gr1000b | C15: 1000.0155 | D15: 0.00015920113 | E15: 0.164378 | F15: 0.00014891608 | G15: 1591.5 | H15: 1.5 | J15: =C15-C$3 -> 1000.0155 | K15: =E15-E$3 -> 0.16435085 | L15: =K15*0.000000001/(2*PI()*J15*G15*0.000000000001) -> 1.6435341e-05 | M15: 1000 | N15: =(J15/M15-1)*1000000 -> 15.494534 | O15: =N15+P$1 -> 13.080394
A16: 44712.484 | B16: es13 | C16: 4.99994 | D16: 8.3522452e-08 | E16: 0.00021248 | F16: 1.0254755e-06 | G16: 1591.5 | H16: 15 | I16: Logger 23.659, GMH 526 23.34 | J16: =C16-C$3 -> 4.9999395 | K16: =E16-E$3 -> 0.00018533 | L16: =K16*0.000000001/(2*PI()*J16*G16*0.000000000001) -> 3.70676e-06 | M16: 5 | N16: =(J16/M16-1)*1000000 -> -12.0976 | O16: =N16+P$1 -> -14.51174
A17: 44712.485 | B17: es16 | C17: 5.0000912 | D17: 5.706137e-08 | E17: 0.00018019 | F17: 1.2389108e-06 | G17: 1591.5 | H17: 15 | J17: =C17-C$3 -> 5.0000907 | K17: =E17-E$3 -> 0.00015304 | L17: =K17*0.000000001/(2*PI()*J17*G17*0.000000000001) -> 3.0608396e-06 | M17: 5 | N17: =(J17/M17-1)*1000000 -> 18.1372 | O17: =N17+P$1 -> 15.72306
A18: 44712.487 | B18: es14 | C18: 0.50004924 | D18: 8.5258431e-08 | E18: 7.392e-05 | F18: 8.4593144e-07 | G18: 1591.5 | H18: 15 | J18: =C18-C$3 -> 0.50004877 | K18: =E18-E$3 -> 4.677e-05 | L18: =K18*0.000000001/(2*PI()*J18*G18*0.000000000001) -> 9.3533781e-06 | M18: 0.5 | N18: =(J18/M18-1)*1000000 -> 97.546 | O18: =N18+P$1 -> 95.13186
A19: 44712.488 | B19: ub1000 | C19: 1000.1484 | D19: 3e-06 | E19: 0.131797 | F19: 0.00012353542 | G19: 1591.5 | H19: 1.5 | I19: pressure 1003.59 mb, GMH 526 under UB1000 20.79 | J19: =C19-C$3 -> 1000.1484 | K19: =E19-E$3 -> 0.13176985 | L19: =K19*0.000000001/(2*PI()*J19*G19*0.000000000001) -> 1.3175439e-05 | M19: 1000 | N19: =(J19/M19-1)*1000000 -> 148.38053 | O19: =N19+P$1 -> 145.96639

Sheet AH2700A2022-06-02
A1: av_exp = 10, frequency = 1591.5, no. of samples = 10, settling samples = 2 | J1: zero_corrected | K1: from G:\Shared drives\MSL - Electricity - Ongoing\Farad\Cap_Scale_Sept_2021\compare 2019 2020.xlsx cell AA30 | M1: AH11C1 | N1: -4.2 | O1: correction | P1: =N1 - N6 -> -2.41679
A2: DateTime | B2: Capacitor | C2: Capacitance (pF) | D2: uCap (pF) | E2: Conductance (nS) | F2: uCond (nS) | G2: Frequency (Hz) | H2: Voltage (V) | J2: Capacitance (pF) | K2: Conductance (nS) | L2: tand | M2: nominal C | N2: error | O2: corrected ppm
A3: 44714.476 | B3: zero | C3: -2.39e-07 | D3: 8.1541401e-08 | E3: 2.672e-05 | F3: 9.335952e-07 | G3: 1591.5 | H3: 15 | I3: AH11_1: 11.9, -11.7, 31.1, .033, -.016, -.010, .017 | J3: =C3-C$3 -> 0 | K3: =D3-D$3 -> 0 | L3: - | N3: ppm
A4: 44714.478 | B4: ah11a1 | C4: 9.9999756 | D4: 6.5886266e-08 | E4: -0.00012229 | F4: 1.0454186e-06 | G4: 1591.5 | H4: 15 | J4: =C4-C$3 -> 9.9999759 | K4: =E4-E$3 -> -0.00014901 | L4: =K4*0.000000001/(2*PI()*J4*G4*0.000000000001) -> -1.4901499e-06 | M4: 10 | N4: =(J4/M4-1)*1000000 -> -2.4118 | O4: =N4+P$1 -> -4.82859
A5: 44714.48 | B5: ah11b1 | C5: 9.9999776 | D5: 8.5556998e-08 | E5: -4.786e-05 | F5: 7.4859869e-07 | G5: 1591.5 | H5: 15 | J5: =C5-C$3 -> 9.9999779 | K5: =E5-E$3 -> -7.458e-05 | L5: =K5*0.000000001/(2*PI()*J5*G5*0.000000000001) -> -7.4582481e-07 | M5: 10 | N5: =(J5/M5-1)*1000000 -> -2.2111 | O5: =N5+P$1 -> -4.62789
A6: 44714.481 | B6: ah11c1 | C6: 99.999821 | D6: 6.6332495e-08 | E6: 0.0017713 | F6: 9e-07 | G6: 1591.5 | H6: 15 | J6: =C6-C$3 -> 99.999822 | K6: =E6-E$3 -> 0.00174458 | L6: =K6*0.000000001/(2*PI()*J6*G6*0.000000000001) -> 1.7446373e-06 | M6: 100 | N6: =(J6/M6-1)*1000000 -> -1.78321 | O6: =N6+P$1 -> -4.2
A7: 44714.482 | B7: ah11d1 | C7: 99.999816 | D7: 1.0049876e-07 | E7: 0.0021451 | F7: 7e-07 | G7: 1591.5 | H7: 15 | I7: AH11_2: 11.8, -11.9, 30.1, -.034, -.048, -.004, .022 | J7: =C7-C$3 -> 99.999816 | K7: =E7-E$3 -> 0.00211838 | L7: =K7*0.000000001/(2*PI()*J7*G7*0.000000000001) -> 2.1184497e-06 | M7: 100 | N7: =(J7/M7-1)*1000000 -> -1.83591 | O7: =N7+P$1 -> -4.2527
A8: 44714.484 | B8: ah11a2 | C8: 9.9999754 | D8: 9.2606695e-08 | E8: -0.00022195 | F8: 9.3834962e-07 | G8: 1591.5 | H8: 15 | J8: =C8-C$3 -> 9.9999757 | K8: =E8-E$3 -> -0.00024867 | L8: =K8*0.000000001/(2*PI()*J8*G8*0.000000000001) -> -2.4867833e-06 | M8: 10 | N8: =(J8/M8-1)*1000000 -> -2.4343 | O8: =N8+P$1 -> -4.85109
A9: 44714.486 | B9: ah11b2 | C9: 9.9999728 | D9: 7.1944423e-08 | E9: -0.00018832 | F9: 1.5822768e-06 | G9: 1591.5 | H9: 15 | J9: =C9-C$3 -> 9.999973 | K9: =E9-E$3 -> -0.00021504 | L9: =K9*0.000000001/(2*PI()*J9*G9*0.000000000001) -> -2.1504726e-06 | M9: 10 | N9: =(J9/M9-1)*1000000 -> -2.7009 | O9: =N9+P$1 -> -5.11769
A10: 44714.487 | B10: ah11c2 | C10: 99.999781 | D10: 1.2206555e-07 | E10: 0.0008548 | F10: 1.1661904e-06 | G10: 1591.5 | H10: 15 | J10: =C10-C$3 -> 99.999781 | K10: =E10-E$3 -> 0.00082808 | L10: =K10*0.000000001/(2*PI()*J10*G10*0.000000000001) -> 8.2810753e-07 | M10: 100 | N10: =(J10/M10-1)*1000000 -> -2.19151 | O10: =N10+P$1 -> -4.6083
A11: 44714.489 | B11: ah11d2 | C11: 99.999857 | D11: 1.2206556e-07 | E11: 0.0009471 | F11: 9.4339811e-07 | G11: 1591.5 | H11: 15 | J11: =C11-C$3 -> 99.999857 | K11: =E11-E$3 -> 0.00092038 | L11: =K11*0.000000001/(2*PI()*J11*G11*0.000000000001) -> 9.204099e-07 | M11: 100 | N11: =(J11/M11-1)*1000000 -> -1.42851 | O11: =N11+P$1 -> -3.8453
A12: 44714.491 | B12: gr10 | C12: 10.000213 | D12: 1.360147e-07 | E12: 0.00090647 | F12: 7.6426435e-07 | G12: 1591.5 | H12: 15 | I12: GR inner 2.006, 993.03 mb, inner is 24.0060 | J12: =C12-C$3 -> 10.000214 | K12: =E12-E$3 -> 0.00087975 | L12: =K12*0.000000001/(2*PI()*J12*G12*0.000000000001) -> 8.7975853e-06 | M12: 10 | N12: =(J12/M12-1)*1000000 -> 21.3589 | O12: =N12+P$1 -> 18.94211
A13: 44714.493 | B13: gr100 | C13: 100.0041 | D13: 0 | E13: 0.0076045 | F13: 1.7916473e-06 | G13: 1591.5 | H13: 15 | J13: =C13-C$3 -> 100.0041 | K13: =E13-E$3 -> 0.00757778 | L13: =K13*0.000000001/(2*PI()*J13*G13*0.000000000001) -> 7.5777044e-06 | M13: 100 | N13: =(J13/M13-1)*1000000 -> 41.04239 | O13: =N13+P$1 -> 38.6256
A14: 44714.494 | B14: gr1000a | C14: 1000.0326 | D14: 4e-06 | E14: 0.169483 | F14: 3.6345564e-05 | G14: 1591.5 | H14: 1.5 | J14: =C14-C$3 -> 1000.0326 | K14: =E14-E$3 -> 0.16945628 | L14: =K14*0.000000001/(2*PI()*J14*G14*0.000000000001) -> 1.6945602e-05 | M14: 1000 | N14: =(J14/M14-1)*1000000 -> 32.568239 | O14: =N14+P$1 -> 30.151449
A15: 44714.496 | B15: gr1000b | C15: 1000.0164 | D15: 0 | E15: 0.172414 | F15: 3.3526109e-05 | G15: 1591.5 | H15: 1.5 | J15: =C15-C$3 -> 1000.0164 | K15: =E15-E$3 -> 0.17238728 | L15: =K15*0.000000001/(2*PI()*J15*G15*0.000000000001) -> 1.723898e-05 | M15: 1000 | N15: =(J15/M15-1)*1000000 -> 16.430239 | O15: =N15+P$1 -> 14.013449
A16: 44714.497 | B16: es13 | C16: 4.9999465 | D16: 6.2e-08 | E16: 0.00022512 | F16: 7.6262704e-07 | G16: 1591.5 | H16: 15 | J16: =C16-C$3 -> 4.9999467 | K16: =E16-E$3 -> 0.0001984 | L16: =K16*0.000000001/(2*PI()*J16*G16*0.000000000001) -> 3.9681655e-06 | M16: 5 | N16: =(J16/M16-1)*1000000 -> -10.651 | O16: =N16+P$1 -> -13.06779
A17: 44714.499 | B17: es16 | C17: 5.0000952 | D17: 7.9849859e-08 | E17: 0.000104 | F17: 1.6774981e-06 | G17: 1591.5 | H17: 15 | I17: Sapphire ball logging 23.660 | J17: =C17-C$3 -> 5.0000954 | K17: =E17-E$3 -> 7.728e-05 | L17: =K17*0.000000001/(2*PI()*J17*G17*0.000000000001) -> 1.5456185e-06 | M17: 5 | N17: =(J17/M17-1)*1000000 -> 19.0874 | O17: =N17+P$1 -> 16.67061
A18: 44714.5 | B18: es14 | C18: 0.50004996 | D18: 8.908423e-08 | E18: 7.65e-05 | F18: 8.508819e-07 | G18: 1591.5 | H18: 15 | J18: =C18-C$3 -> 0.5000502 | K18: =E18-E$3 -> 4.978e-05 | L18: =K18*0.000000001/(2*PI()*J18*G18*0.000000000001) -> 9.9553098e-06 | M18: 0.5 | N18: =(J18/M18-1)*1000000 -> 100.394 | O18: =N18+P$1 -> 97.97721
A19: 44714.502 | B19: ub1000 | C19: 1000.1444 | D19: 4e-06 | E19: 0.149627 | F19: 4.7759816e-05 | G19: 1591.5 | H19: 1.5 | I19: GMH 526 reads 20.76 under UB 1000, reads 23.35 in sapphire ball | J19: =C19-C$3 -> 1000.1444 | K19: =E19-E$3 -> 0.14960028 | L19: =K19*0.000000001/(2*PI()*J19*G19*0.000000000001) -> 1.4958333e-05 | M19: 1000 | N19: =(J19/M19-1)*1000000 -> 144.39224 | O19: =N19+P$1 -> 141.97545

Sheet AH2700A2022-06-20
A1: av_exp = 10, frequency = 1591.5, no. of samples = 10, settling samples = 2 | J1: zero_corrected | K1: from G:\Shared drives\MSL - Electricity - Ongoing\Farad\Cap_Scale_Sept_2021\compare 2019 2020.xlsx cell AA30 | M1: AH11C1 | N1: -4.2 | O1: correction | P1: =N1 - N6 -> -2.39264
A2: DateTime | B2: Capacitor | C2: Capacitance (pF) | D2: uCap (pF) | E2: Conductance (nS) | F2: uCond (nS) | G2: Frequency (Hz) | H2: Voltage (V) | J2: Capacitance (pF) | K2: Conductance (nS) | L2: tand | M2: nominal C | N2: error | O2: corrected ppm
A3: 44732.571 | B3: zero | C3: 1.476e-06 | D3: 7.1021124e-08 | E3: 2.647e-05 | F3: 6.9433421e-07 | G3: 1591.5 | H3: 15 | I3: AH11_1:11.9, -11.7, 31.1, .033, -.016, -.010, .016 | J3: =C3-C$3 -> 0 | K3: =D3-D$3 -> 0 | L3: - | N3: ppm
A4: 44732.572 | B4: ah11a1 | C4: 9.9999755 | D4: 1.1625833e-07 | E4: -0.00014476 | F4: 9.5519631e-07 | G4: 1591.5 | H4: 15 | J4: =C4-C$3 -> 9.9999741 | K4: =E4-E$3 -> -0.00017123 | L4: =K4*0.000000001/(2*PI()*J4*G4*0.000000000001) -> -1.7123576e-06 | M4: 10 | N4: =(J4/M4-1)*1000000 -> -2.5948 | O4: =N4+P$1 -> -4.98744
A5: 44732.574 | B5: ah11b1 | C5: 9.999978 | D5: 1.161034e-07 | E5: -0.00010845 | F5: 1.0278619e-06 | G5: 1591.5 | H5: 15 | J5: =C5-C$3 -> 9.9999766 | K5: =E5-E$3 -> -0.00013492 | L5: =K5*0.000000001/(2*PI()*J5*G5*0.000000000001) -> -1.3492451e-06 | M5: 10 | N5: =(J5/M5-1)*1000000 -> -2.3436 | O5: =N5+P$1 -> -4.73624
A6: 44732.575 | B6: ah11c1 | C6: 99.999821 | D6: 7.9999998e-08 | E6: 0.0017436 | F6: 1.1135529e-06 | G6: 1591.5 | H6: 15 | J6: =C6-C$3 -> 99.999819 | K6: =E6-E$3 -> 0.00171713 | L6: =K6*0.000000001/(2*PI()*J6*G6*0.000000000001) -> 1.7171864e-06 | M6: 100 | N6: =(J6/M6-1)*1000000 -> -1.80736 | O6: =N6+P$1 -> -4.2
A7: 44732.576 | B7: ah11d1 | C7: 99.999816 | D7: 1.0198039e-07 | E7: 0.0021136 | F7: 6.6332496e-07 | G7: 1591.5 | H7: 15 | J7: =C7-C$3 -> 99.999814 | K7: =E7-E$3 -> 0.00208713 | L7: =K7*0.000000001/(2*PI()*J7*G7*0.000000000001) -> 2.0871987e-06 | M7: 100 | N7: =(J7/M7-1)*1000000 -> -1.85716 | O7: =N7+P$1 -> -4.2498
A8: 44732.577 | B8: ah11a2 | C8: 9.9999757 | D8: 9.0138782e-08 | E8: -0.00025677 | F8: 9.9704564e-07 | G8: 1591.5 | H8: 15 | I8: 11.8, -11.9, 30.2, -.033, -.043, -.004, .022 | J8: =C8-C$3 -> 9.9999742 | K8: =E8-E$3 -> -0.00028324 | L8: =K8*0.000000001/(2*PI()*J8*G8*0.000000000001) -> -2.8324953e-06 | M8: 10 | N8: =(J8/M8-1)*1000000 -> -2.5791 | O8: =N8+P$1 -> -4.97174
A9: 44732.579 | B9: ah11b2 | C9: 9.9999732 | D9: 6.1122827e-08 | E9: -0.00021484 | F9: 6.5604878e-07 | G9: 1591.5 | H9: 15 | J9: =C9-C$3 -> 9.9999717 | K9: =E9-E$3 -> -0.00024131 | L9: =K9*0.000000001/(2*PI()*J9*G9*0.000000000001) -> -2.4131818e-06 | M9: 10 | N9: =(J9/M9-1)*1000000 -> -2.8318 | O9: =N9+P$1 -> -5.22444
A10: 44732.58 | B10: ah11c2 | C10: 99.999781 | D10: 9.1651515e-08 | E10: 0.0008196 | F10: 1.1135529e-06 | G10: 1591.5 | H10: 15 | J10: =C10-C$3 -> 99.99978 | K10: =E10-E$3 -> 0.00079313 | L10: =K10*0.000000001/(2*PI()*J10*G10*0.000000000001) -> 7.9315638e-07 | M10: 100 | N10: =(J10/M10-1)*1000000 -> -2.20436 | O10: =N10+P$1 -> -4.597
A11: 44732.582 | B11: ah11d2 | C11: 99.999857 | D11: 1.2489996e-07 | E11: 0.0009067 | F11: 9e-07 | G11: 1591.5 | H11: 15 | J11: =C11-C$3 -> 99.999856 | K11: =E11-E$3 -> 0.00088023 | L11: =K11*0.000000001/(2*PI()*J11*G11*0.000000000001) -> 8.8025861e-07 | M11: 100 | N11: =(J11/M11-1)*1000000 -> -1.44196 | O11: =N11+P$1 -> -3.8346
A12: 44732.584 | B12: gr10 | C12: 10.000206 | D12: 1.1661904e-07 | E12: 0.00090529 | F12: 1.3156367e-06 | G12: 1591.5 | H12: 15 | I12: GR inner 24.0102, 1022.34mbar | J12: =C12-C$3 -> 10.000205 | K12: =E12-E$3 -> 0.00087882 | L12: =K12*0.000000001/(2*PI()*J12*G12*0.000000000001) -> 8.7882932e-06 | M12: 10 | N12: =(J12/M12-1)*1000000 -> 20.4504 | O12: =N12+P$1 -> 18.05776
A13: 44732.587 | B13: gr100 | C13: 100.0041 | D13: 0 | E13: 0.0079161 | F13: 2.1e-06 | G13: 1591.5 | H13: 15 | J13: =C13-C$3 -> 100.00409 | K13: =E13-E$3 -> 0.00788963 | L13: =K13*0.000000001/(2*PI()*J13*G13*0.000000000001) -> 7.889552e-06 | M13: 100 | N13: =(J13/M13-1)*1000000 -> 40.94524 | O13: =N13+P$1 -> 38.5526
A14: 44732.589 | B14: gr1000a | C14: 1000.0327 | D14: 5e-06 | E14: 0.177067 | F14: 3.318132e-05 | G14: 1591.5 | H14: 1.5 | J14: =C14-C$3 -> 1000.0327 | K14: =E14-E$3 -> 0.17704053 | L14: =K14*0.000000001/(2*PI()*J14*G14*0.000000000001) -> 1.7704024e-05 | M14: 1000 | N14: =(J14/M14-1)*1000000 -> 32.703524 | O14: =N14+P$1 -> 30.310884
A15: 44732.592 | B15: gr1000b | C15: 1000.0165 | D15: 4.5825757e-06 | E15: 0.180876 | F15: 2.059126e-05 | G15: 1591.5 | H15: 1.5 | I15: gr1nA read before settle down | J15: =C15-C$3 -> 1000.0165 | K15: =E15-E$3 -> 0.18084953 | L15: =K15*0.000000001/(2*PI()*J15*G15*0.000000000001) -> 1.8085216e-05 | M15: 1000 | N15: =(J15/M15-1)*1000000 -> 16.491524 | O15: =N15+P$1 -> 14.098884
A16: 44732.595 | B16: es13 | C16: 4.9999528 | D16: 6.2e-08 | E16: 0.00022947 | F16: 7.18401e-07 | G16: 1591.5 | H16: 15 | J16: =C16-C$3 -> 4.9999513 | K16: =E16-E$3 -> 0.000203 | L16: =K16*0.000000001/(2*PI()*J16*G16*0.000000000001) -> 4.0601656e-06 | M16: 5 | N16: =(J16/M16-1)*1000000 -> -9.73 | O16: =N16+P$1 -> -12.12264
A17: 44732.596 | B17: es16 | C17: 5.0001002 | D17: 6.0860496e-08 | E17: -6.593e-05 | F17: 2.9506101e-06 | G17: 1591.5 | H17: 15 | J17: =C17-C$3 -> 5.0000987 | K17: =E17-E$3 -> -9.24e-05 | L17: =K17*0.000000001/(2*PI()*J17*G17*0.000000000001) -> -1.8480209e-06 | M17: 5 | N17: =(J17/M17-1)*1000000 -> 19.7476 | O17: =N17+P$1 -> 17.35496
A18: 44732.599 | B18: es14 | C18: 0.50005057 | D18: 5.083306e-08 | E18: 7.562e-05 | F18: 8.9532117e-07 | G18: 1591.5 | H18: 15 | J18: =C18-C$3 -> 0.50004909 | K18: =E18-E$3 -> 4.915e-05 | L18: =K18*0.000000001/(2*PI()*J18*G18*0.000000000001) -> 9.8293403e-06 | M18: 0.5 | N18: =(J18/M18-1)*1000000 -> 98.18 | O18: =N18+P$1 -> 95.78736
A19: 44732.6 | B19: ub1000 | C19: 1000.1567 | D19: 4.8989795e-06 | E19: 0.13761 | F19: 1.6733201e-05 | G19: 1591.5 | H19: 1.5 | I19: S_ball 23.678 GMH*526 20.88 underUB, in oil 23.67 | J19: =C19-C$3 -> 1000.1567 | K19: =E19-E$3 -> 0.13758353 | L19: =K19*0.000000001/(2*PI()*J19*G19*0.000000000001) -> 1.3756625e-05 | M19: 1000 | N19: =(J19/M19-1)*1000000 -> 156.70252 | O19: =N19+P$1 -> 154.30988
A20: 44732.609 | B20: PC1 | C20: 10.000371 | D20: 1.4317821e-07 | E20: 0.00041626 | F20: 1.0180373e-06 | G20: 1591.5 | H20: 15 | J20: =C20-C$3 -> 10.000369 | K20: =E20-E$3 -> 0.00038979 | L20: =K20*0.000000001/(2*PI()*J20*G20*0.000000000001) -> 3.8978772e-06 | M20: 10 | N20: =(J20/M20-1)*1000000 -> 36.9074 | O20: =N20+P$1 -> 34.51476
A21: 44732.61 | B21: PC2 | C21: 10.000106 | D21: 5e-08 | E21: 0.00041752 | F21: 8.3402638e-07 | G21: 1591.5 | H21: 15 | J21: =C21-C$3 -> 10.000105 | K21: =E21-E$3 -> 0.00039105 | L21: =K21*0.000000001/(2*PI()*J21*G21*0.000000000001) -> 3.9105804e-06 | M21: 10 | N21: =(J21/M21-1)*1000000 -> 10.4874 | O21: =N21+P$1 -> 8.09476
A22: 44732.611 | B22: PC3 | C22: 10.000086 | D22: 1.5132746e-07 | E22: 0.00040574 | F22: 1.4058449e-06 | G22: 1591.5 | H22: 15 | J22: =C22-C$3 -> 10.000085 | K22: =E22-E$3 -> 0.00037927 | L22: =K22*0.000000001/(2*PI()*J22*G22*0.000000000001) -> 3.7927856e-06 | M22: 10 | N22: =(J22/M22-1)*1000000 -> 8.4834 | O22: =N22+P$1 -> 6.09076
A23: 44732.612 | B23: PC4 | C23: 10.000178 | D23: 1.3747727e-07 | E23: 0.00043976 | F23: 9.3187982e-07 | G23: 1591.5 | H23: 15 | J23: =C23-C$3 -> 10.000176 | K23: =E23-E$3 -> 0.00041329 | L23: =K23*0.000000001/(2*PI()*J23*G23*0.000000000001) -> 4.1329555e-06 | M23: 10 | N23: =(J23/M23-1)*1000000 -> 17.6214 | O23: =N23+P$1 -> 15.22876
A24: 44732.613 | B24: PC5 | C24: 9.9999905 | D24: 1.5285287e-07 | E24: 0.00041015 | F24: 1.285496e-06 | G24: 1591.5 | H24: 15 | J24: =C24-C$3 -> 9.999989 | K24: =E24-E$3 -> 0.00038368 | L24: =K24*0.000000001/(2*PI()*J24*G24*0.000000000001) -> 3.8369234e-06 | M24: 10 | N24: =(J24/M24-1)*1000000 -> -1.1022 | O24: =N24+P$1 -> -3.49484
A25: 44732.614 | B25: PC6 | C25: 10.000183 | D25: 1.1135529e-07 | E25: 0.00044035 | F25: 1.2745587e-06 | G25: 1591.5 | H25: 15 | J25: =C25-C$3 -> 10.000182 | K25: =E25-E$3 -> 0.00041388 | L25: =K25*0.000000001/(2*PI()*J25*G25*0.000000000001) -> 4.1388534e-06 | M25: 10 | N25: =(J25/M25-1)*1000000 -> 18.1584 | O25: =N25+P$1 -> 15.76576
A26: 44732.618 | B26: PC7 | C26: 10.000314 | D26: 1.6155494e-07 | E26: 0.00042545 | F26: 1.1002272e-06 | G26: 1591.5 | H26: 15 | J26: =C26-C$3 -> 10.000313 | K26: =E26-E$3 -> 0.00039898 | L26: =K26*0.000000001/(2*PI()*J26*G26*0.000000000001) -> 3.9897992e-06 | M26: 10 | N26: =(J26/M26-1)*1000000 -> 31.2594 | O26: =N26+P$1 -> 28.86676
A27: 44732.62 | B27: PC8 | C27: 10.000222 | D27: 1.5132746e-07 | E27: 0.00042754 | F27: 1.5140674e-06 | G27: 1591.5 | H27: 15 | I27: Permuteable Temp 21.0 FCU11 20.9 44.23%RH | J27: =C27-C$3 -> 10.00022 | K27: =E27-E$3 -> 0.00040107 | L27: =K27*0.000000001/(2*PI()*J27*G27*0.000000000001) -> 4.0107362e-06 | M27: 10 | N27: =(J27/M27-1)*1000000 -> 22.0234 | O27: =N27+P$1 -> 19.63076
A28: 44732.622 | B28: PC9 | C28: 10.000346 | D28: 1.7776389e-07 | E28: 0.00042912 | F28: 1.2528368e-06 | G28: 1591.5 | H28: 15 | J28: =C28-C$3 -> 10.000344 | K28: =E28-E$3 -> 0.00040265 | L28: =K28*0.000000001/(2*PI()*J28*G28*0.000000000001) -> 4.0264864e-06 | M28: 10 | N28: =(J28/M28-1)*1000000 -> 34.4444 | O28: =N28+P$1 -> 32.05176
A29: 44732.624 | B29: PC10 | C29: 10.000419 | D29: 1.356466e-07 | E29: 0.00042361 | F29: 1.0940293e-06 | G29: 1591.5 | H29: 15 | J29: =C29-C$3 -> 10.000417 | K29: =E29-E$3 -> 0.00039714 | L29: =K29*0.000000001/(2*PI()*J29*G29*0.000000000001) -> 3.9713576e-06 | M29: 10 | N29: =(J29/M29-1)*1000000 -> 41.7484 | O29: =N29+P$1 -> 39.35576
A30: 44732.625 | B30: PC11 | C30: 10.000221 | D30: 1.183216e-07 | E30: 0.00041694 | F30: 8.6510115e-07 | G30: 1591.5 | H30: 15 | J30: =C30-C$3 -> 10.00022 | K30: =E30-E$3 -> 0.00039047 | L30: =K30*0.000000001/(2*PI()*J30*G30*0.000000000001) -> 3.9047354e-06 | M30: 10 | N30: =(J30/M30-1)*1000000 -> 21.9824 | O30: =N30+P$1 -> 19.58976

Sheet AH2700A2022-06-21WZP
A1: av_exp = 10, frequency = 1591.5, no. of samples = 10, settling samples = 2 | J1: zero_corrected | K1: from G:\Shared drives\MSL - Electricity - Ongoing\Farad\Cap_Scale_Sept_2021\compare 2019 2020.xlsx cell AA30 | M1: AH11C1 | N1: -4.2 | O1: correction | P1: =N1 - N6 -> -2.2915
A2: DateTime | B2: Capacitor | C2: Capacitance (pF) | D2: uCap (pF) | E2: Conductance (nS) | F2: uCond (nS) | G2: Frequency (Hz) | H2: Voltage (V) | J2: Capacitance (pF) | K2: Conductance (nS) | L2: tand | M2: nominal C | N2: error | O2: corrected ppm
A3: 44733.005 | B3: zero | C3: 1.2e-05 | D3: 3e-07 | E3: 1.69e-05 | F3: 5.08e-06 | G3: 1591.5 | H3: 15 | I3: AH11_1:11.9, -11.7, 31.1, .033, -.016, -.010, .016 | J3: =C3-C$3 -> 0 | K3: =D3-D$3 -> 0 | L3: - | N3: ppm
A4: 44733.007 | B4: ah11a1 | C4: 9.9999757 | D4: 1.14e-07 | E4: -0.00012074 | F4: 7.09e-07 | G4: 1591.5 | H4: 15 | J4: =C4-C$3 -> 9.9999637 | K4: =E4-E$3 -> -0.00013764 | L4: =K4*0.000000001/(2*PI()*J4*G4*0.000000000001) -> -1.3764477e-06 | M4: 10 | N4: =(J4/M4-1)*1000000 -> -3.6251 | O4: =N4+P$1 -> -5.9166
A5: 44733.008 | B5: ah11b1 | C5: 9.9999781 | D5: 7.95e-08 | E5: -7.15e-05 | F5: 7.31e-07 | G5: 1591.5 | H5: 15 | J5: =C5-C$3 -> 9.9999661 | K5: =E5-E$3 -> -8.84e-05 | L5: =K5*0.000000001/(2*PI()*J5*G5*0.000000000001) -> -8.8403045e-07 | M5: 10 | N5: =(J5/M5-1)*1000000 -> -3.3896 | O5: =N5+P$1 -> -5.6811
A6: 44733.009 | B6: ah11c1 | C6: 99.999821 | D6: 1.02e-07 | E6: 0.0017608 | F6: 1.08e-06 | G6: 1591.5 | H6: 15 | J6: =C6-C$3 -> 99.999809 | K6: =E6-E$3 -> 0.0017439 | L6: =K6*0.000000001/(2*PI()*J6*G6*0.000000000001) -> 1.7439575e-06 | M6: 100 | N6: =(J6/M6-1)*1000000 -> -1.9085 | O6: =N6+P$1 -> -4.2
A7: 44733.01 | B7: ah11d1 | C7: 99.999816 | D7: 1.17e-07 | E7: 0.0021344 | F7: 1.11e-06 | G7: 1591.5 | H7: 15 | J7: =C7-C$3 -> 99.999804 | K7: =E7-E$3 -> 0.0021175 | L7: =K7*0.000000001/(2*PI()*J7*G7*0.000000000001) -> 2.1175699e-06 | M7: 100 | N7: =(J7/M7-1)*1000000 -> -1.9598 | O7: =N7+P$1 -> -4.2513
A8: 44733.012 | B8: ah11a2 | C8: 9.9999758 | D8: 7.91e-08 | E8: -0.00022942 | F8: 1.11e-06 | G8: 1591.5 | H8: 15 | I8: AH11_2:11.8, -11.9, 30.3, -.033, -.042, -.003, .022 | J8: =C8-C$3 -> 9.9999638 | K8: =E8-E$3 -> -0.00024632 | L8: =K8*0.000000001/(2*PI()*J8*G8*0.000000000001) -> -2.4632854e-06 | M8: 10 | N8: =(J8/M8-1)*1000000 -> -3.6179 | O8: =N8+P$1 -> -5.9094
A9: 44733.014 | B9: ah11b2 | C9: 9.9999733 | D9: 8.75e-08 | E9: -0.00019704 | F9: 9.92e-07 | G9: 1591.5 | H9: 15 | J9: =C9-C$3 -> 9.9999613 | K9: =E9-E$3 -> -0.00021394 | L9: =K9*0.000000001/(2*PI()*J9*G9*0.000000000001) -> -2.1394747e-06 | M9: 10 | N9: =(J9/M9-1)*1000000 -> -3.866 | O9: =N9+P$1 -> -6.1575
A10: 44733.016 | B10: ah11c2 | C10: 99.999781 | D10: 1.42e-07 | E10: 0.0008355 | F10: 9.22e-07 | G10: 1591.5 | H10: 15 | J10: =C10-C$3 -> 99.999769 | K10: =E10-E$3 -> 0.0008186 | L10: =K10*0.000000001/(2*PI()*J10*G10*0.000000000001) -> 8.1862731e-07 | M10: 100 | N10: =(J10/M10-1)*1000000 -> -2.3077 | O10: =N10+P$1 -> -4.5992
A11: 44733.017 | B11: ah11d2 | C11: 99.999857 | D11: 9.22e-08 | E11: 0.0009229 | F11: 1.14e-06 | G11: 1591.5 | H11: 15 | J11: =C11-C$3 -> 99.999845 | K11: =E11-E$3 -> 0.000906 | L11: =K11*0.000000001/(2*PI()*J11*G11*0.000000000001) -> 9.0602954e-07 | M11: 100 | N11: =(J11/M11-1)*1000000 -> -1.5465 | O11: =N11+P$1 -> -3.838
A12: 44733.018 | B12: gr10 | C12: 10.000204 | D12: 1.28e-07 | E12: 0.00087585 | F12: 1.15e-06 | G12: 1591.5 | H12: 15 | I12: GR inner 23.9840, 1025.59mbar | J12: =C12-C$3 -> 10.000192 | K12: =E12-E$3 -> 0.00085895 | L12: =K12*0.000000001/(2*PI()*J12*G12*0.000000000001) -> 8.5896017e-06 | M12: 10 | N12: =(J12/M12-1)*1000000 -> 19.224 | O12: =N12+P$1 -> 16.9325
A13: 44733.021 | B13: gr100 | C13: 100.00409 | D13: 3e-07 | E13: 0.0077844 | F13: 2.76e-06 | G13: 1591.5 | H13: 15 | J13: =C13-C$3 -> 100.00408 | K13: =E13-E$3 -> 0.0077675 | L13: =K13*0.000000001/(2*PI()*J13*G13*0.000000000001) -> 7.7674243e-06 | M13: 100 | N13: =(J13/M13-1)*1000000 -> 40.811 | O13: =N13+P$1 -> 38.5195
A14: 44733.024 | B14: gr1000a | C14: 1000.0327 | D14: 4e-06 | E14: 0.177769 | F14: 2.7e-05 | G14: 1591.5 | H14: 1.5 | J14: =C14-C$3 -> 1000.0327 | K14: =E14-E$3 -> 0.1777521 | L14: =K14*0.000000001/(2*PI()*J14*G14*0.000000000001) -> 1.7775181e-05 | M14: 1000 | N14: =(J14/M14-1)*1000000 -> 32.7 | O14: =N14+P$1 -> 30.4085
A15: 44733.026 | B15: gr1000b | C15: 1000.0162 | D15: 0.00060536 | E15: 0.185458 | F15: 0.000531786 | G15: 1591.5 | H15: 1.5 | J15: =C15-C$3 -> 1000.0162 | K15: =E15-E$3 -> 0.1854411 | L15: =K15*0.000000001/(2*PI()*J15*G15*0.000000000001) -> 1.8544386e-05 | M15: 1000 | N15: =(J15/M15-1)*1000000 -> 16.151 | O15: =N15+P$1 -> 13.8595
A16: 44733.028 | B16: es13 | C16: 4.999953 | D16: 3.66e-08 | E16: 0.00023808 | F16: 7.77e-07 | G16: 1591.5 | H16: 15 | J16: =C16-C$3 -> 4.999941 | K16: =E16-E$3 -> 0.00022118 | L16: =K16*0.000000001/(2*PI()*J16*G16*0.000000000001) -> 4.4237896e-06 | M16: 5 | N16: =(J16/M16-1)*1000000 -> -11.7906 | O16: =N16+P$1 -> -14.0821
A17: 44733.029 | B17: es16 | C17: 5.0001004 | D17: 8.96e-08 | E17: 0.00014061 | F17: 1.71e-05 | G17: 1591.5 | H17: 15 | J17: =C17-C$3 -> 5.0000884 | K17: =E17-E$3 -> 0.00012371 | L17: =K17*0.000000001/(2*PI()*J17*G17*0.000000000001) -> 2.4742331e-06 | M17: 5 | N17: =(J17/M17-1)*1000000 -> 17.6872 | O17: =N17+P$1 -> 15.3957
A18: 44733.031 | B18: es14 | C18: 0.50005079 | D18: 8.63e-08 | E18: 7.65e-05 | F18: 7.88e-07 | G18: 1591.5 | H18: 15 | J18: =C18-C$3 -> 0.50003879 | K18: =E18-E$3 -> 5.96e-05 | L18: =K18*0.000000001/(2*PI()*J18*G18*0.000000000001) -> 1.1919446e-05 | M18: 0.5 | N18: =(J18/M18-1)*1000000 -> 77.578 | O18: =N18+P$1 -> 75.2865
A19: 44733.033 | B19: ub1000 | C19: 1000.1582 | D19: 4.47e-06 | E19: 0.135994 | F19: 3.01e-05 | G19: 1591.5 | H19: 1.5 | I19: S-ball 23.6794 GMH*526 20.81 under UB cap, in oil 23.37 | J19: =C19-C$3 -> 1000.1582 | K19: =E19-E$3 -> 0.1359771 | L19: =K19*0.000000001/(2*PI()*J19*G19*0.000000000001) -> 1.3595981e-05 | M19: 1000 | N19: =(J19/M19-1)*1000000 -> 158.198 | O19: =N19+P$1 -> 155.9065
A20: 44733.036 | B20: PC1 | C20: 10.000361 | D20: 2.28e-07 | E20: 0.00038683 | F20: 6.96e-06 | G20: 1591.5 | H20: 15 | I20: Permuteable Temp 21.54 in oil bath no oil, FCU11 Valsala offline | J20: =C20-C$3 -> 10.000349 | K20: =E20-E$3 -> 0.00036993 | L20: =K20*0.000000001/(2*PI()*J20*G20*0.000000000001) -> 3.6992857e-06 | M20: 10 | N20: =(J20/M20-1)*1000000 -> 34.917 | O20: =N20+P$1 -> 32.6255
A21: 44733.037 | B21: PC2 | C21: 10.000101 | D21: 2.33e-07 | E21: 0.00032805 | F21: 8.07e-06 | G21: 1591.5 | H21: 15 | J21: =C21-C$3 -> 10.000089 | K21: =E21-E$3 -> 0.00031115 | L21: =K21*0.000000001/(2*PI()*J21*G21*0.000000000001) -> 3.1115689e-06 | M21: 10 | N21: =(J21/M21-1)*1000000 -> 8.915 | O21: =N21+P$1 -> 6.6235
A22: 44733.04 | B22: PC3 | C22: 10.00008 | D22: 1.48e-07 | E22: 0.00020109 | F22: 1.43e-06 | G22: 1591.5 | H22: 15 | J22: =C22-C$3 -> 10.000068 | K22: =E22-E$3 -> 0.00018419 | L22: =K22*0.000000001/(2*PI()*J22*G22*0.000000000001) -> 1.8419448e-06 | M22: 10 | N22: =(J22/M22-1)*1000000 -> 6.75 | O22: =N22+P$1 -> 4.4585
A23: 44733.041 | B23: PC4 | C23: 10.000174 | D23: 1.3e-07 | E23: 0.00042711 | F23: 1.48e-06 | G23: 1591.5 | H23: 15 | J23: =C23-C$3 -> 10.000162 | K23: =E23-E$3 -> 0.00041021 | L23: =K23*0.000000001/(2*PI()*J23*G23*0.000000000001) -> 4.1021608e-06 | M23: 10 | N23: =(J23/M23-1)*1000000 -> 16.231 | O23: =N23+P$1 -> 13.9395
A24: 44733 | B24: PC5 | C24: 9.9999693 | D24: 1.01e-07 | E24: 0.00028139 | F24: 1.36e-06 | G24: 1591.5 | H24: 15 | J24: =C24-C$3 -> 9.9999573 | K24: =E24-E$3 -> 0.00026449 | L24: =K24*0.000000001/(2*PI()*J24*G24*0.000000000001) -> 2.6449935e-06 | M24: 10 | N24: =(J24/M24-1)*1000000 -> -4.2743 | O24: =N24+P$1 -> -6.5658
A25: 44733.001 | B25: PC6 | C25: 10.000181 | D25: 1.28e-07 | E25: 0.00041969 | F25: 1.54e-06 | G25: 1591.5 | H25: 15 | J25: =C25-C$3 -> 10.000169 | K25: =E25-E$3 -> 0.00040279 | L25: =K25*0.000000001/(2*PI()*J25*G25*0.000000000001) -> 4.0279572e-06 | M25: 10 | N25: =(J25/M25-1)*1000000 -> 16.866 | O25: =N25+P$1 -> 14.5745
A26: 44733.002 | B26: PC7 | C26: 10.000303 | D26: 1.66e-07 | E26: 0.00038531 | F26: 1.39e-06 | G26: 1591.5 | H26: 15 | J26: =C26-C$3 -> 10.000291 | K26: =E26-E$3 -> 0.00036841 | L26: =K26*0.000000001/(2*PI()*J26*G26*0.000000000001) -> 3.6841071e-06 | M26: 10 | N26: =(J26/M26-1)*1000000 -> 29.122 | O26: =N26+P$1 -> 26.8305
A27: 44733.003 | B27: PC8 | C27: 10.000214 | D27: 2.16e-07 | E27: 0.00038247 | F27: 1.89e-06 | G27: 1591.5 | H27: 15 | J27: =C27-C$3 -> 10.000202 | K27: =E27-E$3 -> 0.00036557 | L27: =K27*0.000000001/(2*PI()*J27*G27*0.000000000001) -> 3.6557396e-06 | M27: 10 | N27: =(J27/M27-1)*1000000 -> 20.235 | O27: =N27+P$1 -> 17.9435
A28: 44733.004 | B28: PC9 | C28: 10.000337 | D28: 1.1e-07 | E28: 0.00030429 | F28: 1.42e-06 | G28: 1591.5 | H28: 15 | J28: =C28-C$3 -> 10.000325 | K28: =E28-E$3 -> 0.00028739 | L28: =K28*0.000000001/(2*PI()*J28*G28*0.000000000001) -> 2.8738957e-06 | M28: 10 | N28: =(J28/M28-1)*1000000 -> 32.54 | O28: =N28+P$1 -> 30.2485
A29: 44733.005 | B29: PC10 | C29: 10.000401 | D29: 8e-08 | E29: 0.00034054 | F29: 1.39e-06 | G29: 1591.5 | H29: 15 | J29: =C29-C$3 -> 10.000389 | K29: =E29-E$3 -> 0.00032364 | L29: =K29*0.000000001/(2*PI()*J29*G29*0.000000000001) -> 3.2363746e-06 | M29: 10 | N29: =(J29/M29-1)*1000000 -> 38.906 | O29: =N29+P$1 -> 36.6145
A30: 44733.006 | B30: PC11 | C30: 10.00021 | D30: 1.47e-07 | E30: 0.00035638 | F30: 2.87e-06 | G30: 1591.5 | H30: 15 | J30: =C30-C$3 -> 10.000198 | K30: =E30-E$3 -> 0.00033948 | L30: =K30*0.000000001/(2*PI()*J30*G30*0.000000000001) -> 3.3948384e-06 | M30: 10 | N30: =(J30/M30-1)*1000000 -> 19.758 | O30: =N30+P$1 -> 17.4665

Sheet AH2700A2022-06-21
A1: av_exp = 10, frequency = 1591.5, no. of samples = 10, settling samples = 2 | J1: zero_corrected | K1: from G:\Shared drives\MSL - Electricity - Ongoing\Farad\Cap_Scale_Sept_2021\compare 2019 2020.xlsx cell AA30 | M1: AH11C1 | N1: -4.2 | O1: correction | P1: =N1 - N6 -> -2.41672
A2: DateTime | B2: Capacitor | C2: Capacitance (pF) | D2: uCap (pF) | E2: Conductance (nS) | F2: uCond (nS) | G2: Frequency (Hz) | H2: Voltage (V) | J2: Capacitance (pF) | K2: Conductance (nS) | L2: tand | M2: nominal C | N2: error | O2: corrected ppm
A3: 44733.624 | B3: zero | C3: 9.8e-08 | D3: 8.3282651e-08 | E3: 2.732e-05 | F3: 6.6151342e-07 | G3: 1591.5 | H3: 15 | I3: AH11_1:11.9, -11.7, 31.2, .033, -.016, -.010, .016 | J3: =C3-C$3 -> 0 | K3: =D3-D$3 -> 0 | L3: - | N3: ppm
A4: 44733.625 | B4: ah11a1 | C4: 9.9999758 | D4: 8.9442719e-08 | E4: -0.00013245 | F4: 6.946222e-07 | G4: 1591.5 | H4: 15 | J4: =C4-C$3 -> 9.9999758 | K4: =E4-E$3 -> -0.00015977 | L4: =K4*0.000000001/(2*PI()*J4*G4*0.000000000001) -> -1.5977535e-06 | M4: 10 | N4: =(J4/M4-1)*1000000 -> -2.4248 | O4: =N4+P$1 -> -4.84152
